Workbook

Sheet members
A1: member_id | B1: user_id | C1: name | D1: join_date | E1: skill_level | F1: email | G1: lifetime_points | H1: status_tier | I1: total_wins | J1: total_losses | K1: win_rate | L1: phone_number
A2: M0001 | B2: 1 | C2: Hung | D2: 46174 | E2: BEGINNER+ | F2: anandazhou09@gmail.com | G2: =IF($A$2<>"",SUMIF(RESULT!D:D,members!$A$2,RESULT!I:I),"") -> 432 | H2: CLUB | I2: =IF($A2<>"",SUMIF(RESULT!D:D,members!$A2,RESULT!J:J),"") -> 79 | J2: =IF($A2<>"",SUMIF(RESULT!D:D,members!$A2,RESULT!K:K),"") -> 40 | K2: =I2/(I2+J2)*100 -> 66.386555 | L2: 6285190094868
A3: M0002 | B3: 2 | C3: Vaness | D3: 46174 | E3: BEGINNER | F3: vanessafebry97@gmail.com | G3: =IF(A3<>"",SUMIF(RESULT!D:D,members!A3,RESULT!I:I),"") -> 145 | H3: DIAMOND | I3: =IF($A3<>"",SUMIF(RESULT!D:D,members!$A3,RESULT!J:J),"") -> 19 | J3: =IF($A3<>"",SUMIF(RESULT!D:D,members!$A3,RESULT!K:K),"") -> 59 | K3: =I3/(I3+J3)*100 -> 24.358974 | L3: 6282220502003
A4: M0003 | B4: 3 | C4: Adhyasta | D4: 46174 | E4: BEGINNER | F4: Idabagusadhya@gmail.com | G4: =IF(A4<>"",SUMIF(RESULT!D:D,members!A4,RESULT!I:I),"") -> 135 | H4: DIAMOND | I4: =IF($A4<>"",SUMIF(RESULT!D:D,members!$A4,RESULT!J:J),"") -> 20 | J4: =IF($A4<>"",SUMIF(RESULT!D:D,members!$A4,RESULT!K:K),"") -> 16 | K4: =I4/(I4+J4)*100 -> 55.555556 | L4: NULL
A5: M0004 | B5: 4 | C5: NADIA | D5: 46174 | E5: BEGINNER | F5: indahnadiaswarii@gmail.com | G5: =IF(A5<>"",SUMIF(RESULT!D:D,members!A5,RESULT!I:I),"") -> 39 | H5: DIAMOND | I5: =IF($A5<>"",SUMIF(RESULT!D:D,members!$A5,RESULT!J:J),"") -> 7 | J5: =IF($A5<>"",SUMIF(RESULT!D:D,members!$A5,RESULT!K:K),"") -> 14 | K5: =I5/(I5+J5)*100 -> 33.333333 | L5: NULL
A6: M0005 | B6: 5 | C6: Abiseka | D6: 46174 | E6: BEGINNER | F6: abiseka33@gmail.com | G6: =IF(A6<>"",SUMIF(RESULT!D:D,members!A6,RESULT!I:I),"") -> 122 | H6: DIAMOND | I6: =IF($A6<>"",SUMIF(RESULT!D:D,members!$A6,RESULT!J:J),"") -> 23 | J6: =IF($A6<>"",SUMIF(RESULT!D:D,members!$A6,RESULT!K:K),"") -> 17 | K6: =I6/(I6+J6)*100 -> 57.5 | L6: NULL
A7: M0006 | B7: 6 | C7: ECAK | D7: 46174 | E7: BEGINNER | F7: sangayuecak@gmail.com | G7: =IF(A7<>"",SUMIF(RESULT!D:D,members!A7,RESULT!I:I),"") -> 71 | H7: DIAMOND | I7: =IF($A7<>"",SUMIF(RESULT!D:D,members!$A7,RESULT!J:J),"") -> 9 | J7: =IF($A7<>"",SUMIF(RESULT!D:D,members!$A7,RESULT!K:K),"") -> 24 | K7: =I7/(I7+J7)*100 -> 27.272727 | L7: NULL
A8: M0007 | B8: 7 | C8: ALDI | D8: 46174 | E8: BEGINNER+ | F8: NULL | G8: =IF(A8<>"",SUMIF(RESULT!D:D,members!A8,RESULT!I:I),"") -> 80 | H8: DIAMOND | I8: =IF($A8<>"",SUMIF(RESULT!D:D,members!$A8,RESULT!J:J),"") -> 17 | J8: =IF($A8<>"",SUMIF(RESULT!D:D,members!$A8,RESULT!K:K),"") -> 12 | K8: =I8/(I8+J8)*100 -> 58.62069 | L8: NULL
A9: M0008 | B9: 8 | C9: IVAN T | D9: 46174 | E9: BEGINNER+ | F9: NULL | G9: =IF(A9<>"",SUMIF(RESULT!D:D,members!A9,RESULT!I:I),"") -> 0 | H9: DIAMOND | I9: =IF($A9<>"",SUMIF(RESULT!D:D,members!$A9,RESULT!J:J),"") -> 0 | J9: =IF($A9<>"",SUMIF(RESULT!D:D,members!$A9,RESULT!K:K),"") -> 0 | K9: 0 | L9: NULL
A10: M0009 | B10: 9 | C10: REVATA | D10: 46174 | E10: BEGINNER+ | F10: revatasiriananda@gmail.com | G10: =IF(A10<>"",SUMIF(RESULT!D:D,members!A10,RESULT!I:I),"") -> 199 | H10: DIAMOND | I10: =IF($A10<>"",SUMIF(RESULT!D:D,members!$A10,RESULT!J:J),"") -> 33 | J10: =IF($A10<>"",SUMIF(RESULT!D:D,members!$A10,RESULT!K:K),"") -> 17 | K10: =I10/(I10+J10)*100 -> 66 | L10: NULL
A11: M0010 | B11: 10 | C11: AYUDITA | D11: 46174 | E11: BEGINNER+ | F11: kmgayudita35@gmail.com | G11: =IF(A11<>"",SUMIF(RESULT!D:D,members!A11,RESULT!I:I),"") -> 16 | H11: DIAMOND | I11: =IF($A11<>"",SUMIF(RESULT!D:D,members!$A11,RESULT!J:J),"") -> 3 | J11: =IF($A11<>"",SUMIF(RESULT!D:D,members!$A11,RESULT!K:K),"") -> 4 | K11: =I11/(I11+J11)*100 -> 42.857143 | L11: NULL
A12: M0011 | B12: 11 | C12: NANDIYA | D12: 46174 | E12: L. BEGINNER | F12: nandiyakarunadh@gmail.com | G12: =IF(A12<>"",SUMIF(RESULT!D:D,members!A12,RESULT!I:I),"") -> 23 | H12: DIAMOND | I12: =IF($A12<>"",SUMIF(RESULT!D:D,members!$A12,RESULT!J:J),"") -> 3 | J12: =IF($A12<>"",SUMIF(RESULT!D:D,members!$A12,RESULT!K:K),"") -> 11 | K12: =I12/(I12+J12)*100 -> 21.428571 | L12: NULL
A13: M0012 | B13: 12 | C13: HENRY | D13: 46174 | E13: L. BEGINNER | F13: NULL | G13: =IF(A13<>"",SUMIF(RESULT!D:D,members!A13,RESULT!I:I),"") -> 11 | H13: DIAMOND | I13: =IF($A13<>"",SUMIF(RESULT!D:D,members!$A13,RESULT!J:J),"") -> 1 | J13: =IF($A13<>"",SUMIF(RESULT!D:D,members!$A13,RESULT!K:K),"") -> 6 | K13: =I13/(I13+J13)*100 -> 14.285714 | L13: NULL
A14: M0013 | B14: 13 | C14: RIAN Y | D14: 46197 | E14: BEGINNER+ | F14: yuliawanrian@gmail.com | G14: =IF(A14<>"",SUMIF(RESULT!D:D,members!A14,RESULT!I:I),"") -> 92 | H14: DIAMOND | I14: =IF($A14<>"",SUMIF(RESULT!D:D,members!$A14,RESULT!J:J),"") -> 17 | J14: =IF($A14<>"",SUMIF(RESULT!D:D,members!$A14,RESULT!K:K),"") -> 4 | K14: =I14/(I14+J14)*100 -> 80.952381 | L14: NULL
A15: M0014 | B15: 14 | C15: OKA | D15: 46197 | E15: L. INTERMEDIATE | F15: okamobi123@gmail.com | G15: =IF(A15<>"",SUMIF(RESULT!D:D,members!A15,RESULT!I:I),"") -> 42 | H15: DIAMOND | I15: =IF($A15<>"",SUMIF(RESULT!D:D,members!$A15,RESULT!J:J),"") -> 9 | J15: =IF($A15<>"",SUMIF(RESULT!D:D,members!$A15,RESULT!K:K),"") -> 5 | K15: =I15/(I15+J15)*100 -> 64.285714 | L15: NULL
A16: M0015 | B16: 15 | C16: IWAN | D16: 46197 | E16: BEGINNER | F16: aliridwankk@gmail.com | G16: =IF(A16<>"",SUMIF(RESULT!D:D,members!A16,RESULT!I:I),"") -> 22 | H16: DIAMOND | I16: =IF($A16<>"",SUMIF(RESULT!D:D,members!$A16,RESULT!J:J),"") -> 4 | J16: =IF($A16<>"",SUMIF(RESULT!D:D,members!$A16,RESULT!K:K),"") -> 3 | K16: =I16/(I16+J16)*100 -> 57.142857 | L16: NULL
A17: M0016 | B17: 16 | C17: BAGUS G | D17: 46197 | E17: L. BEGINNER | F17: gusgarlicka@gmail.com | G17: =IF(A17<>"",SUMIF(RESULT!D:D,members!A17,RESULT!I:I),"") -> 49 | H17: DIAMOND | I17: =IF($A17<>"",SUMIF(RESULT!D:D,members!$A17,RESULT!J:J),"") -> 5 | J17: =IF($A17<>"",SUMIF(RESULT!D:D,members!$A17,RESULT!K:K),"") -> 21 | K17: =I17/(I17+J17)*100 -> 19.230769 | L17: NULL
A18: M0017 | B18: 17 | C18: YUDHA | D18: 46197 | E18: L. BEGINNER | F18: Yudha.arthawijaya@gmail.com | G18: =IF(A18<>"",SUMIF(RESULT!D:D,members!A18,RESULT!I:I),"") -> 27 | H18: DIAMOND | I18: =IF($A18<>"",SUMIF(RESULT!D:D,members!$A18,RESULT!J:J),"") -> 2 | J18: =IF($A18<>"",SUMIF(RESULT!D:D,members!$A18,RESULT!K:K),"") -> 10 | K18: =I18/(I18+J18)*100 -> 16.666667 | L18: NULL
A19: M0018 | B19: 18 | C19: BHASKARA | D19: 46198 | E19: BEGINNER+ | F19: bagusbhaskara14@gmail.com | G19: =IF(A19<>"",SUMIF(RESULT!D:D,members!A19,RESULT!I:I),"") -> 28 | H19: DIAMOND | I19: =IF($A19<>"",SUMIF(RESULT!D:D,members!$A19,RESULT!J:J),"") -> 4 | J19: =IF($A19<>"",SUMIF(RESULT!D:D,members!$A19,RESULT!K:K),"") -> 1 | K19: =I19/(I19+J19)*100 -> 80 | L19: NULL
A20: M0019 | B20: 19 | C20: GUS YANA | D20: 46198 | E20: BEGINNER+ | F20: wiradnyana99@gmail.com | G20: =IF(A20<>"",SUMIF(RESULT!D:D,members!A20,RESULT!I:I),"") -> 50 | H20: DIAMOND | I20: =IF($A20<>"",SUMIF(RESULT!D:D,members!$A20,RESULT!J:J),"") -> 7 | J20: =IF($A20<>"",SUMIF(RESULT!D:D,members!$A20,RESULT!K:K),"") -> 3 | K20: =I20/(I20+J20)*100 -> 70 | L20: NULL
A21: M0020 | B21: 20 | C21: SEKAR TABSKUY | D21: 46198 | E21: BEGINNER | F21: sekarletlora@gmail.com | G21: =IF(A21<>"",SUMIF(RESULT!D:D,members!A21,RESULT!I:I),"") -> 82 | H21: DIAMOND | I21: =IF($A21<>"",SUMIF(RESULT!D:D,members!$A21,RESULT!J:J),"") -> 9 | J21: =IF($A21<>"",SUMIF(RESULT!D:D,members!$A21,RESULT!K:K),"") -> 11 | K21: =I21/(I21+J21)*100 -> 45 | L21: NULL
... A47: M0046 | B47: 46 | C47: RIZAL | D47: 46218 | E47: BEGINNER | F47: NULL | G47: =IF(A47<>"",SUMIF(RESULT!D:D,members!A47,RESULT!I:I),"") -> 22 | H47: DIAMOND | I47: =IF($A47<>"",SUMIF(RESULT!D:D,members!$A47,RESULT!J:J),"") -> 3 | J47: =IF($A47<>"",SUMIF(RESULT!D:D,members!$A47,RESULT!K:K),"") -> 2 | K47: =I47/(I47+J47)*100 -> 60 | L47: NULL
A48: M0047 | B48: 47 | C48: ELSYE | D48: NULL | E48: BEGINNER | F48: NULL | G48: =IF(A48<>"",SUMIF(RESULT!D:D,members!A48,RESULT!I:I),"") -> 16 | H48: DIAMOND | I48: =IF($A48<>"",SUMIF(RESULT!D:D,members!$A48,RESULT!J:J),"") -> 1 | J48: =IF($A48<>"",SUMIF(RESULT!D:D,members!$A48,RESULT!K:K),"") -> 4 | K48: =I48/(I48+J48)*100 -> 20 | L48: NULL
A49: M0048 | B49: 48 | C49: RICAT | D49: NULL | E49: BEGINNER | F49: NULL | G49: =IF(A49<>"",SUMIF(RESULT!D:D,members!A49,RESULT!I:I),"") -> 18 | H49: DIAMOND | I49: =IF($A49<>"",SUMIF(RESULT!D:D,members!$A49,RESULT!J:J),"") -> 4 | J49: =IF($A49<>"",SUMIF(RESULT!D:D,members!$A49,RESULT!K:K),"") -> 3 | K49: =I49/(I49+J49)*100 -> 57.142857 | L49: NULL
A50: M0049 | B50: 49 | C50: Varien | D50: 46220 | E50: BEGINNER | F50: variensa22@gmail.com | G50: =IF(A50<>"",SUMIF(RESULT!D:D,members!A50,RESULT!I:I),"") -> 26 | H50: DIAMOND | I50: =IF($A50<>"",SUMIF(RESULT!D:D,members!$A50,RESULT!J:J),"") -> 5 | J50: =IF($A50<>"",SUMIF(RESULT!D:D,members!$A50,RESULT!K:K),"") -> 9 | K50: =I50/(I50+J50)*100 -> 35.714286 | L50: NULL
A51: M0050 | B51: 50 | C51: Relin Tania | D51: 46220 | E51: BEGINNER | F51: relintania1@gmail.com | G51: =IF(A51<>"",SUMIF(RESULT!D:D,members!A51,RESULT!I:I),"") -> 11 | H51: DIAMOND | I51: =IF($A51<>"",SUMIF(RESULT!D:D,members!$A51,RESULT!J:J),"") -> 1 | J51: =IF($A51<>"",SUMIF(RESULT!D:D,members!$A51,RESULT!K:K),"") -> 6 | K51: =I51/(I51+J51)*100 -> 14.285714 | L51: NULL
A52: M0051 | B52: 51 | C52: Andrian | D52: 46222 | E52: BEGINNER+ | F52: andrian.wijaya2001@gmail.com | G52: =IF(A52<>"",SUMIF(RESULT!D:D,members!A52,RESULT!I:I),"") -> 35 | H52: DIAMOND | I52: =IF($A52<>"",SUMIF(RESULT!D:D,members!$A52,RESULT!J:J),"") -> 6 | J52: =IF($A52<>"",SUMIF(RESULT!D:D,members!$A52,RESULT!K:K),"") -> 2 | K52: =I52/(I52+J52)*100 -> 75 | L52: NULL
A53: M0052 | B53: 52 | C53: DEVA NUGRAHA | D53: 46222 | E53: BEGINNER+ | F53: devanugraha.photoworks@gmail.com | G53: =IF(A53<>"",SUMIF(RESULT!D:D,members!A53,RESULT!I:I),"") -> 97 | H53: DIAMOND | I53: =IF($A53<>"",SUMIF(RESULT!D:D,members!$A53,RESULT!J:J),"") -> 18 | J53: =IF($A53<>"",SUMIF(RESULT!D:D,members!$A53,RESULT!K:K),"") -> 9 | K53: =I53/(I53+J53)*100 -> 66.666667 | L53: NULL
A54: M0053 | B54: 53 | C54: ADI NUGRAHA | D54: NULL | E54: BEGINNER+ | F54: NULL | G54: =IF(A54<>"",SUMIF(RESULT!D:D,members!A54,RESULT!I:I),"") -> 0 | H54: DIAMOND | I54: =IF($A54<>"",SUMIF(RESULT!D:D,members!$A54,RESULT!J:J),"") -> 0 | J54: =IF($A54<>"",SUMIF(RESULT!D:D,members!$A54,RESULT!K:K),"") -> 0 | K54: =I54/(I54+J54)*100 -> #DIV/0! | L54: NULL
A55: M0054 | B55: 54 | C55: Ariyudha IB | D55: 46224 | E55: BEGINNER+ | F55: e.ariyudha08@gmail.com | G55: =IF(A55<>"",SUMIF(RESULT!D:D,members!A55,RESULT!I:I),"") -> 70 | H55: DIAMOND | I55: =IF($A55<>"",SUMIF(RESULT!D:D,members!$A55,RESULT!J:J),"") -> 9 | J55: =IF($A55<>"",SUMIF(RESULT!D:D,members!$A55,RESULT!K:K),"") -> 1 | K55: =I55/(I55+J55)*100 -> 90 | L55: NULL
A56: M0055 | B56: 55 | C56: GUSDE | D56: NULL | E56: BEGINNER+ | F56: NULL | G56: =IF(A56<>"",SUMIF(RESULT!D:D,members!A56,RESULT!I:I),"") -> 0 | H56: DIAMOND | I56: =IF($A56<>"",SUMIF(RESULT!D:D,members!$A56,RESULT!J:J),"") -> 0 | J56: =IF($A56<>"",SUMIF(RESULT!D:D,members!$A56,RESULT!K:K),"") -> 0 | K56: =I56/(I56+J56)*100 -> #DIV/0! | L56: NULL
A57: M0056 | B57: 56 | C57: Kaon Hasegawa | D57: 46224 | E57: BEGINNER+ | F57: kaonhasegawa55@gmail.com | G57: =IF(A57<>"",SUMIF(RESULT!D:D,members!A57,RESULT!I:I),"") -> 51 | H57: DIAMOND | I57: =IF($A57<>"",SUMIF(RESULT!D:D,members!$A57,RESULT!J:J),"") -> 6 | J57: =IF($A57<>"",SUMIF(RESULT!D:D,members!$A57,RESULT!K:K),"") -> 7 | K57: =I57/(I57+J57)*100 -> 46.153846 | L57: NULL
A58: M0057 | B58: 57 | C58: Kadek Ana Dwijayanti | D58: 46226 | E58: BEGINNER | F58: ana.dwijayanti10@gmail.com | G58: =IF(A58<>"",SUMIF(RESULT!D:D,members!A58,RESULT!I:I),"") -> 28 | H58: DIAMOND | I58: =IF($A58<>"",SUMIF(RESULT!D:D,members!$A58,RESULT!J:J),"") -> 3 | J58: =IF($A58<>"",SUMIF(RESULT!D:D,members!$A58,RESULT!K:K),"") -> 2 | K58: =I58/(I58+J58)*100 -> 60 | L58: NULL
A59: M0058 | B59: 58 | C59: B.02.Albert Gunawan | D59: 46223 | E59: BEGINNER | F59: albertgunawang@gmail.com | G59: =IF(A59<>"",SUMIF(RESULT!D:D,members!A59,RESULT!I:I),"") -> 12 | H59: DIAMOND | I59: =IF($A59<>"",SUMIF(RESULT!D:D,members!$A59,RESULT!J:J),"") -> 2 | J59: =IF($A59<>"",SUMIF(RESULT!D:D,members!$A59,RESULT!K:K),"") -> 5 | K59: =I59/(I59+J59)*100 -> 28.571429 | L59: NULL
A60: M0059 | B60: 59 | C60: jason darmadi | D60: 46229 | E60: BEGINNER+ | F60: darmadijason@gmail.com | G60: =IF(A60<>"",SUMIF(RESULT!D:D,members!A60,RESULT!I:I),"") -> 35 | H60: DIAMOND | I60: =IF($A60<>"",SUMIF(RESULT!D:D,members!$A60,RESULT!J:J),"") -> 6 | J60: =IF($A60<>"",SUMIF(RESULT!D:D,members!$A60,RESULT!K:K),"") -> 2 | K60: =I60/(I60+J60)*100 -> 75 | L60: NULL
A61: M0060 | B61: 60 | C61: Detha Nata Ganendra | D61: 46229 | E61: BEGINNER+ | F61: dethanataganendra@gmail.com | G61: =IF(A61<>"",SUMIF(RESULT!D:D,members!A61,RESULT!I:I),"") -> 28 | H61: DIAMOND | I61: =IF($A61<>"",SUMIF(RESULT!D:D,members!$A61,RESULT!J:J),"") -> 6 | J61: =IF($A61<>"",SUMIF(RESULT!D:D,members!$A61,RESULT!K:K),"") -> 2 | K61: =I61/(I61+J61)*100 -> 75 | L61: NULL
A62: M0061 | B62: 61 | C62: Yuvinta Riandisty | D62: 46229 | E62: BEGINNER | F62: yuvinta.r@gmail.com | G62: =IF(A62<>"",SUMIF(RESULT!D:D,members!A62,RESULT!I:I),"") -> 16 | H62: DIAMOND | I62: =IF($A62<>"",SUMIF(RESULT!D:D,members!$A62,RESULT!J:J),"") -> 5 | J62: =IF($A62<>"",SUMIF(RESULT!D:D,members!$A62,RESULT!K:K),"") -> 3 | K62: =I62/(I62+J62)*100 -> 62.5 | L62: NULL
A63: M0062 | B63: 62 | C63: Yuvan Gunawan | D63: 46229 | E63: L. BEGINNER | F63: ypgunawan@gmail.com | G63: =IF(A63<>"",SUMIF(RESULT!D:D,members!A63,RESULT!I:I),"") -> 11 | H63: DIAMOND | I63: =IF($A63<>"",SUMIF(RESULT!D:D,members!$A63,RESULT!J:J),"") -> 1 | J63: =IF($A63<>"",SUMIF(RESULT!D:D,members!$A63,RESULT!K:K),"") -> 7 | K63: =I63/(I63+J63)*100 -> 12.5 | L63: NULL
A64: M0063 | B64: 63 | C64: Revin Almadani | D64: 46230 | E64: BEGINNER+ | F64: revinalmadani00@gmail.com | G64: =IF(A64<>"",SUMIF(RESULT!D:D,members!A64,RESULT!I:I),"") -> 28 | H64: DIAMOND | I64: =IF($A64<>"",SUMIF(RESULT!D:D,members!$A64,RESULT!J:J),"") -> 5 | J64: =IF($A64<>"",SUMIF(RESULT!D:D,members!$A64,RESULT!K:K),"") -> 2 | K64: =I64/(I64+J64)*100 -> 71.428571 | L64: NULL
A65: M0064 | B65: 64 | C65: Arya Janardana | D65: 46230 | E65: BEGINNER+ | F65: janardanaarya@gmail.com | G65: =IF(A65<>"",SUMIF(RESULT!D:D,members!A65,RESULT!I:I),"") -> 22 | H65: DIAMOND | I65: =IF($A65<>"",SUMIF(RESULT!D:D,members!$A65,RESULT!J:J),"") -> 4 | J65: =IF($A65<>"",SUMIF(RESULT!D:D,members!$A65,RESULT!K:K),"") -> 3 | K65: =I65/(I65+J65)*100 -> 57.142857 | L65: NULL
...

Sheet users
A1: id | B1: name | C1: email | D1: avatar | E1: google_id | F1: email_verified_at | G1: password | H1: remember_token | I1: created_at | J1: updated_at
A2: 1 | B2: Hung | C2: anandazhou09@gmail.com | D2: /storage/avatars/muuM5jVCFSjl9tAEthAzEI3xI8FqErutsBcRNykl.jpg | E2: 1.0845854e+20 | F2: NULL | G2: $2y$12$UwdxgDZUKj.EyGXpa7VwxOvqQwvEiQ66hCiaHIny4YEDGOuuWRJ7. | H2: 2QDepm2HQPIepb0tDMXWhPpZ2DHacPAH5kDxW85RmCqnOqoxqpJsocmdy3bp | I2: 46217.706 | J2: 46219.464
A3: 2 | B3: Vaness | C3: vanessafebry97@gmail.com | D3: https://lh3.googleusercontent.com/a/ACg8ocIT5D4bPpwPRIXtT9-AOIsxjQgH3LUcD53UHVwxDqvR8WMdcrOn=s96-c | E3: 1.1520986e+20 | F3: NULL | G3: $2y$12$1IVqrN92IsIT2gkrKO6A0OmVvUzx8lJSsFobP6VqJVfCA.BSrI/Xe | H3: c8vsk3TM3tAHwJ5g4qDsRgiTdMZTN4W2JHMVzdv0ar6hgo7F74JyVsHfFV1V | I3: 46217.706 | J3: 46219.152
A4: 3 | B4: Adhyasta | C4: Idabagusadhya@gmail.com | D4: /storage/avatars/CRz36Wyrf63uIJWmbYGSE6i5kN8ZoMN532CXp5O9.jpg | E4: 1.0687577e+20 | F4: NULL | G4: $2y$12$VbgDiDFhVzx5wGN9wAIAC.R1REbz0QITcUrTkqPOUeUUjYPMx/QrG | H4: fWB4ZGimBZq7VhZipoIgQHIX30MLKVFEWQoQwkieMtsOowIH83EY2PegiXHW | I4: 46217.706 | J4: 46219.602
A5: 4 | B5: NADIA | C5: indahnadiaswarii@gmail.com | D5: NULL | E5: NULL | F5: NULL | G5: $2y$12$qtgP9rl/1WC.eogUJc9I5OF587lPD8GK/QE1ZFkkMm9vuVdsY/vCK | H5: NULL | I5: 46217.706 | J5: 46217.706
A6: 5 | B6: Abiseka | C6: abiseka33@gmail.com | D6: /storage/avatars/2H8VMXrvvz9nZAscwWPuoksL1gbhgtxdxl61bdNA.jpg | E6: 1.0582253e+20 | F6: NULL | G6: $2y$12$mjBWuVa8.i9j2AOjlXl6EugTQv5chOZMlJ4bSPD7j7udTmuja2yo2 | H6: 7XkWcN3VeZzTQS3irsvpQDC7UEwad8kvDwcVnbyuKDL04U68MOIpuMc0JYq6 | I6: 46217.706 | J6: 46219.128
A7: 6 | B7: ECAK | C7: sangayuecak@gmail.com | D7: https://lh3.googleusercontent.com/a/ACg8ocJigH-Jx43IIio4pF9ERVJ-skZR9EhWA4_XpRNRCYUkoGyMow=s96-c | E7: 1.1602417e+20 | F7: NULL | G7: $2y$12$azfuPaapBIaAyD9me5AbxOWwrqvtHWdQtrqOjLo0fudKD9dCEn7Vm | H7: HmmhACsQdmO9GvblHxQqGeM9nEUVG9VDmpmVzKZTdt57t7Y9yc2egn9NzyEB | I7: 46217.706 | J7: 46234.522
A8: 7 | B8: ALDI | C8: aldi@example.com | D8: NULL | E8: NULL | F8: NULL | G8: $2y$12$w44k/xNd6yV9NWNMkW2CreRutACJqntIvNaT6Poe5hKGdB0bPzlUq | H8: NULL | I8: 46217.706 | J8: 46217.706
A9: 8 | B9: IVAN T | C9: ivant@example.com | D9: NULL | E9: NULL | F9: NULL | G9: $2y$12$e0l6IOUxVqBIItXmqpqjYOw0bEH25B0oUgvvrdxVg31OpxbG4AEha | H9: NULL | I9: 46217.706 | J9: 46217.706
A10: 9 | B10: REVATA | C10: revatasiriananda@gmail.com | D10: https://lh3.googleusercontent.com/a/ACg8ocK3quvbpEbugm3-w2d0CyiPaBK1yCMmNnZmcywQRs-g1gzWWOdc=s96-c | E10: 1.0086384e+20 | F10: NULL | G10: $2y$12$wVygRnLtqhUNjCoY37Wsa.xGeJHA3EWiMerPEfTs.AWUFFuuO1y3G | H10: R4Qq0hTjE3YNzSUT9YTfmq9Tp5RLZBFapmq1dKL2bh8LOgu1mKmhZCYnLuXB | I10: 46217.706 | J10: 46220.454
A11: 10 | B11: AYUDITA | C11: kmgayudita35@gmail.com | D11: NULL | E11: NULL | F11: NULL | G11: $2y$12$eeycIRskbt93mXQYGatU3uYVmYl0WYAG0VKHVtFE7WCApBY43qWpS | H11: NULL | I11: 46217.706 | J11: 46217.706
A12: 11 | B12: NANDIYA | C12: nandiyakarunadh@gmail.com | D12: NULL | E12: NULL | F12: NULL | G12: $2y$12$gMkXvOltQyfwpaM8cS65XenDHdC49K6F7oKxT7shYt0BcqbSrkcU2 | H12: NULL | I12: 46217.706 | J12: 46217.706
A13: 12 | B13: HENRY | C13: henry@example.com | D13: NULL | E13: NULL | F13: NULL | G13: $2y$12$1jXc2x8DY4RxnLIrbL.FRepC6vuQ9MRxHX2ugZPYhY2.2lwG3bNVi | H13: NULL | I13: 46217.706 | J13: 46217.706
A14: 13 | B14: RIAN Y | C14: yuliawanrian@gmail.com | D14: NULL | E14: NULL | F14: NULL | G14: $2y$12$AdOqbvuQSXbPOXASnTtfkOYx85EOasYqH0YVFyNNdh5Kb8RaOQWbS | H14: NULL | I14: 46217.706 | J14: 46217.706
A15: 14 | B15: OKA | C15: okamobi123@gmail.com | D15: NULL | E15: NULL | F15: NULL | G15: $2y$12$naPo7ENpXICe0Lx5rDxTvur23TjrJ1qV28H6A5f/jbMC0cmyh30hG | H15: NULL | I15: 46217.706 | J15: 46217.706
A16: 15 | B16: IWAN | C16: aliridwankk@gmail.com | D16: NULL | E16: NULL | F16: NULL | G16: $2y$12$UnxuW5UvofzUOe63bZQkBuuMmuDMQKjm32eP7iAgO7snaLGNFzI0y | H16: NULL | I16: 46217.706 | J16: 46217.706
A17: 16 | B17: BAGUS G | C17: gusgarlicka@gmail.com | D17: NULL | E17: NULL | F17: NULL | G17: $2y$12$WoAxc2QOon6uX/Bq5nsZB.5bMowoyEa8ifsGU0V2V47n5OD8ivNcy | H17: NULL | I17: 46217.706 | J17: 46217.706
A18: 17 | B18: YUDHA | C18: Yudha.arthawijaya@gmail.com | D18: https://lh3.googleusercontent.com/a/ACg8ocJdFdspHdWbNHVK2S9sLmZYMXzH5IokEFZKJYw_HGM2YWcnVN8O=s96-c | E18: 1.094438e+20 | F18: NULL | G18: $2y$12$0XYnjVRSWK0wLj0BXGB42e3.eAUmN4WJSkH9hdWxl9vbIzKxic26W | H18: qqRRg6Bl6FdZRCCNAya3GpypBxhwlAj3Q6dHxyF4b85pzcCjiYFDholhptGH | I18: 46217.706 | J18: 46222.22
A19: 18 | B19: BHASKARA | C19: bagusbhaskara14@gmail.com | D19: NULL | E19: NULL | F19: NULL | G19: $2y$12$IKGWHYKcFlEyyFggwSsiauXtOlOElX9NArq/6nS443yAueLbxEAOa | H19: NULL | I19: 46217.706 | J19: 46217.706
A20: 19 | B20: GUS YANA | C20: wiradnyana99@gmail.com | D20: NULL | E20: NULL | F20: NULL | G20: $2y$12$tAsUAUrfPuoGmjdm6LLVbuc/bc7pYT8rIkK5se4NUnauIwjLjciUe | H20: NULL | I20: 46217.706 | J20: 46217.706
A21: 20 | B21: SEKAR W | C21: sekar.letlora@yahoo.com | D21: NULL | E21: NULL | F21: NULL | G21: $2y$12$f4w.Z4pkp8Nv1S3Gg1AM2ex4pGXZZdHNpnfEoMgeEDvf6Yz9ireCu | H21: NULL | I21: 46217.706 | J21: 46217.706
A22: 21 | B22: MENTARI | C22: lidyamentari31@gmail.com | D22: https://lh3.googleusercontent.com/a/ACg8ocKIp0OVV-cvGWsrL6Ezd6OZLjh15niYyfYMkp1rkKKTYN8Q-g7Z8A=s96-c | E22: 1.0400209e+20 | F22: NULL | G22: $2y$12$YpGj4fuX/TEyJtFgWvw9HeFBj5hZYJ9LDlJEQ9yHWV/1efVb7lLLq | H22: oJineEHnEPS2ecsnBQqvosqmY1Zl3dK297vBSKLe3D0NhBlMxBDKbu8Rpyy2 | I22: 46217.706 | J22: 46219.463
A23: 22 | B23: WIRA | C23: kadekadhiwirayudha@gmail.com | D23: NULL | E23: NULL | F23: NULL | G23: $2y$12$HeQbAd8dew6S/1/ZX9BvkehAbe4Q8hgQgtU4geeEpjeSqKTbkmH8C | H23: NULL | I23: 46217.706 | J23: 46217.706
A24: 23 | B24: TRISNA | C24: itrisnajaya@outlook.com | D24: NULL | E24: NULL | F24: NULL | G24: $2y$12$dAtAphToYhPYRwUb9pk2We2AWO9k9d.SF9GazMMmMgpB1vcHs8sqa | H24: NULL | I24: 46217.706 | J24: 46217.706
A25: 24 | B25: RIRI | C25: triyana.recovery@gmail.com | D25: NULL | E25: NULL | F25: NULL | G25: $2y$12$0KaSl.BVP95dQLbJ69s1qemrcniN53r2jSpiH9WWGTqrZzIgPG6UC | H25: NULL | I25: 46217.706 | J25: 46217.706
A26: 25 | B26: OKY | C26: okypetter@gmail.com | D26: NULL | E26: NULL | F26: NULL | G26: $2y$12$SwNrLUjtpNixZxalRheAL.jCVOTEwNnqXXMGr9zn.PF19.Rzdm3qC | H26: NULL | I26: 46217.706 | J26: 46217.706
A27: 26 | B27: AFIN | C27: rama.tannaya@gmail.com | D27: https://lh3.googleusercontent.com/a/ACg8ocKJrfts45yqHIJKkf1WqWGRyqpVBlggXkCq44IjG_L_cG-RDU8sGA=s96-c | E27: 1.0696979e+20 | F27: NULL | G27: $2y$12$y.j6U/GvHQaxo1ha6rPI3eYsicJ/WBhO8lcPbr/eShpHXv4gGhNgG | H27: s6pROdBHjZJnasDsE2XUZlxrZqPtGjNY0qKKyBy63mj9UmVWLzRaYxTbxxQw | I27: 46217.706 | J27: 46220.455
A28: 27 | B28: DIANA | C28: diana@example.com | D28: NULL | E28: NULL | F28: NULL | G28: $2y$12$3/mCKMHG/5TyQV8DYQrYBeAOo2DARhO0B7OojKrfPXn9lzPeq14kO | H28: NULL | I28: 46217.706 | J28: 46217.706
A29: 28 | B29: RAKA S | C29: rakaprasetya.lie@gmail.com | D29: https://lh3.googleusercontent.com/a/ACg8ocLlAZeJWGcuyPTS6x2riYxanFKSDeTvRZHBZZsulKGBa40zwH8=s96-c | E29: 1.1392438e+20 | F29: NULL | G29: $2y$12$N.GPaGohCpTZSlpbHEJoleu9AVoKQJT9BOxkfdmSJna8rBSHUPrJK | H29: OkvqRWE0ad5abuWR9dXp9GiN1tsXwqMqHlM4sqzqv48dY9jSMrubQi9ZXxW6 | I29: 46217.706 | J29: 46219.455
A30: 29 | B30: QUIK | C30: dedwisaptarahadi@gmail.com | D30: https://lh3.googleusercontent.com/a/ACg8ocLbuB7OtTfqe-f1GBW3n6PknXZGZyxMvPcbIajzx-871c3wvh58=s96-c | E30: 1.1158103e+20 | F30: NULL | G30: $2y$12$U81/OL9bw1ccsKyi3iRlSOsi.A3rgNTKBr4pLB87Qcb3hhKyYABSK | H30: dMXzxkqzseCgSzOgnQbWtJGQNdIsYYR8xZ81vPeYih0l91YF4o4bvDFz4FKw | I30: 46217.706 | J30: 46225.181
A31: 30 | B31: STEPHEN | C31: stephensutanto123@gmail.com | D31: NULL | E31: NULL | F31: NULL | G31: $2y$12$msjr6JzyK5XO4ebdXc/C4uOqLMjNNXWy1ql3xNnsui5E.rPYGE9eq | H31: NULL | I31: 46217.706 | J31: 46217.706
A32: 31 | B32: OLIVIA | C32: oliviadean170@gmail.com | D32: https://lh3.googleusercontent.com/a/ACg8ocJfqvGxYtQn_kEnAv9rtSSdE_wDDeDMPjFA5d9v6eLLOek0ifQ=s96-c | E32: 1.0178218e+20 | F32: NULL | G32: $2y$12$lmS3eD/fbwyofmykdFVOrudwo7GHKcjutxeLfANTirurgnFgw4dKu | H32: kzPr3Pinb48w9jopzxf7pfLwQiAIUOzKt01pfOztRjj2DEXgKumkUcyRkfkm | I32: 46217.706 | J32: 46219.45
A33: 32 | B33: PIBBLEBULAT | C33: putudiahdamayanti1406@gmail.com | D33: https://lh3.googleusercontent.com/a/ACg8ocJgvSkUGjLhIM38eytCRGAdSAPnM-V6sS6apJ3xOYE6C00HRvk=s96-c | E33: 1.062717e+20 | F33: NULL | G33: $2y$12$PhDXFCX2kzapb3aCOIwN1eBUd5HavC17Pr4HxOfqSmn04gH7LF6Ei | H33: rxZs2Api27srvGdQU9PycmkStyOrqdlskYUavVQAOczinPGM1dSpFJE747JL | I33: 46217.706 | J33: 46219.456
A34: 33 | B34: WILSON | C34: agusnathayana@gmail.com | D34: https://lh3.googleusercontent.com/a/ACg8ocJyCvCrrd7zNUuoYN49dzrCPfTMCgtXWoydhjZCHpZvpHv1697r=s96-c | E34: 1.0791994e+20 | F34: NULL | G34: $2y$12$AruR4U1mzLfceNTBHw33O.j.LUS0/dHwz.pi9I7rYLvyJmBgqBxLu | H34: lXp6wRrX05vg4hY5jH1f9Mis5e0XRMwGJogbNkPMF5PG9lbr7B7VUrtESHsn | I34: 46217.706 | J34: 46224.357
A35: 34 | B35: RISTYA | C35: ristyanara@gmail.com | D35: NULL | E35: NULL | F35: NULL | G35: $2y$12$wv1Mihj5V7DyCudagwwX5.PP4ChJjwgScai4WoBoGkwfxlW9WYsUe | H35: NULL | I35: 46217.706 | J35: 46217.706
A36: 35 | B36: AHRI | C36: ahriansyahm@gmail.com | D36: NULL | E36: NULL | F36: NULL | G36: $2y$12$6Fp2t5ocuBTJJpzK71aN2O.YGVt2FONg4uEVRT90Dm8f/rqxOguqy | H36: NULL | I36: 46217.706 | J36: 46217.706
A37: 36 | B37: NAYA | C37: nayaka2870@gmail.com | D37: https://lh3.googleusercontent.com/a/ACg8ocIfupzgUCqLAKvqtEu6oM8pqBAsl8v1PpXVhmUhRnvsgiCR2VDq=s96-c | E37: 1.1322957e+20 | F37: NULL | G37: $2y$12$Wsi/U/bL6R1raczLG6jTP.rY4FlmK7h4Z6q.pacwTabacyjE1hXKq | H37: By49xNc8P8ZDMHr1xanCtbsGPzI9iFOYaKaCFWsiWh1H37Ec9haIoxqZ1ADt | I37: 46217.706 | J37: 46222.374
A38: 37 | B38: WULAN | C38: wulantrisnap@gmail.com | D38: https://lh3.googleusercontent.com/a/ACg8ocJO7MhCJ3gx4uhfuSQr7z_9s-yq32UKAveoNYYJxWNCKCykuz3g3g=s96-c | E38: 1.1401624e+20 | F38: NULL | G38: $2y$12$NaKEPkdHBD3ET3p.d407nOAlCnQHnaepTL8EP07y2KCeW3eVakF7a | H38: cbtp5F34euf1vQYTrCZI6DnEzlWDrZp58cTVC6i7l2g8jrUteILn1zHJ6iYY | I38: 46217.706 | J38: 46222.402
A39: 38 | B39: TEGUH | C39: ftk2704@gmail.com | D39: https://lh3.googleusercontent.com/a/ACg8ocK_IP4glYYuZsJiy1AzkYQ3EdUq2NjqEt6KikqGE01Cejyz8A=s96-c | E39: 1.0423026e+20 | F39: NULL | G39: $2y$12$/JNtqV.VcDbMyiCnOeejmew6thuBmBKthAVTdhmOueQXyxQo1vJdi | H39: d0KRwWSbzwBFlDFnFIK48kc24CWdIP3O33h01QIWBsbuDUUgUchZkZEl3G6h | I39: 46217.706 | J39: 46222.29
A40: 39 | B40: UCIK | C40: kanjengyuichiro@gmail.com | D40: NULL | E40: NULL | F40: NULL | G40: $2y$12$TnaRjZcHEXybpf/NkiEpRuKQMD5bfZRgkUd/FkFOOyjn1VhhwuM7W | H40: NULL | I40: 46217.706 | J40: 46217.706
...

Sheet RESULT
A1: result_id | B1: event_id | C1: result_date | D1: member_id | E1: name | F1: finish | G1: placement_bonus | H1: attendance | I1: event_points | J1: wins | K1: losses | L1: diff
A2: 293 | B2: E0001 | C2: 46204 | D2: M0001 | E2: HUNG | F2: 2 | G2: 18 | H2: 10 | I2: 28 | J2: 5 | K2: 2 | L2: 9
A3: 294 | B3: E0001 | C3: 46204 | D3: M0002 | E3: VANESS | F3: 6 | G3: 4 | H3: 10 | I3: 14 | J3: 2 | K3: 5 | L3: -9
A4: 295 | B4: E0001 | C4: 46204 | D4: M0005 | E4: ABISEKA J | F4: 4 | G4: 8 | H4: 10 | I4: 18 | J4: 4 | K4: 3 | L4: 2
A5: 296 | B5: E0001 | C5: 46204 | D5: M0007 | E5: ALDI | F5: 3 | G5: 12 | H5: 10 | I5: 22 | J5: 5 | K5: 2 | L5: 7
A6: 297 | B6: E0001 | C6: 46204 | D6: M0009 | E6: REVATA | F6: 1 | G6: 25 | H6: 10 | I6: 35 | J6: 6 | K6: 1 | L6: 5
A7: 298 | B7: E0001 | C7: 46204 | D7: M0010 | E7: AYUDITA | F7: 5 | G7: 6 | H7: 10 | I7: 16 | J7: 3 | K7: 4 | L7: 0
A8: 299 | B8: E0001 | C8: 46204 | D8: M0011 | E8: NANDIYA | F8: 7 | G8: 2 | H8: 10 | I8: 12 | J8: 2 | K8: 5 | L8: -10
A9: 300 | B9: E0001 | C9: 46204 | D9: M0012 | E9: HENRY | F9: 8 | G9: 1 | H9: 10 | I9: 11 | J9: 1 | K9: 6 | L9: -14
A10: 301 | B10: E0002 | C10: 46204 | D10: M0001 | E10: HUNG | F10: 6 | G10: 4 | H10: 10 | I10: 14 | J10: 2 | K10: 5 | L10: -5
A11: 302 | B11: E0002 | C11: 46204 | D11: M0005 | E11: ABISEKA J | F11: 4 | G11: 8 | H11: 10 | I11: 18 | J11: 3 | K11: 4 | L11: -2
A12: 303 | B12: E0002 | C12: 46204 | D12: M0006 | E12: ECAK | F12: 5 | G12: 6 | H12: 10 | I12: 16 | J12: 3 | K12: 4 | L12: -2
A13: 304 | B13: E0002 | C13: 46204 | D13: M0013 | E13: RIAN Y | F13: 1 | G13: 25 | H13: 10 | I13: 35 | J13: 7 | K13: 0 | L13: 15
... A179: 470 | B179: E0025 | C179: 46234 | D179: M0028 | E179: RAKA S | F179: 8 | G179: 1 | H179: 10 | I179: 11 | J179: 0 | K179: 7 | L179: -11
A180: 274 | B180: E0026 | C180: 46236 | D180: M0006 | E180: ECAK | F180: 8 | G180: 1 | H180: 10 | I180: =SUM(G180:H180) -> 11 | J180: 1 | K180: 6 | L180: -11
A181: 275 | B181: E0026 | C181: 46236 | D181: M0036 | E181: NAYA | F181: 5 | G181: 6 | H181: 10 | I181: =SUM(G181:H181) -> 16 | J181: 3 | K181: 4 | L181: -3
A182: 276 | B182: E0026 | C182: 46236 | D182: M0002 | E182: Vaness | F182: 6 | G182: 4 | H182: 10 | I182: =SUM(G182:H182) -> 14 | J182: 2 | K182: 5 | L182: -5
A183: 277 | B183: E0026 | C183: 46236 | D183: M0098 | E183: Muz | F183: 7 | G183: 2 | H183: 10 | I183: =SUM(G183:H183) -> 12 | J183: 2 | K183: 5 | L183: 8
A184: 278 | B184: E0026 | C184: 46236 | D184: M0099 | E184: Bela (Nabila Savitri) | F184: 1 | G184: 25 | H184: 10 | I184: =SUM(G184:H184) -> 35 | J184: 6 | K184: 1 | L184: 7
A185: 279 | B185: E0026 | C185: 46236 | D185: M0038 | E185: TEGUH | F185: 2 | G185: 18 | H185: 10 | I185: =SUM(G185:H185) -> 28 | J185: 5 | K185: 2 | L185: 10
A186: 280 | B186: E0026 | C186: 46236 | D186: M0100 | E186: Nesya Kerin Anggafita | F186: 4 | G186: 8 | H186: 10 | I186: =SUM(G186:H186) -> 18 | J186: 4 | K186: 3 | L186: 4
A187: 281 | B187: E0026 | C187: 46236 | D187: M0101 | E187: Aplikasi Fahmi | F187: 3 | G187: 12 | H187: 10 | I187: =SUM(G187:H187) -> 22 | J187: 5 | K187: 2 | L187: 6
A188: 471 | B188: E0044 | C188: 46237 | D188: M0136 | E188: Revo Society | F188: 7 | G188: 2 | H188: 10 | I188: =SUM(G188:H188) -> 12 | J188: 3 | K188: 5 | L188: -7
A189: 472 | B189: E0044 | C189: 46237 | D189: M0052 | E189: DEVA NUGRAHA | F189: 3 | G189: 12 | H189: 10 | I189: =SUM(G189:H189) -> 22 | J189: 4 | K189: 4 | L189: 6
A190: 473 | B190: E0044 | C190: 46237 | D190: M0122 | E190: Ngurah Adi | F190: 4 | G190: 8 | H190: 10 | I190: =SUM(G190:H190) -> 18 | J190: 4 | K190: 4 | L190: -1
A191: 474 | B191: E0044 | C191: 46237 | D191: M0056 | E191: Kaon Hasegawa | F191: 1 | G191: 25 | H191: 10 | I191: =SUM(G191:H191) -> 35 | J191: 5 | K191: 3 | L191: 5
... A201: 284 | B201: E0048 | C201: 46295 | D201: M0110 | E201: TDC ADMIND | F201: 1 | G201: 25 | H201: 10 | I201: =SUM(G201:H201) -> 35 | J201: 6 | K201: 1 | L201: 6
